Workbook

Sheet Hướng dẫn
A1: StayGuard: checklist diễn tập (Gate 1)
A2: Cập nhật 03/10/2026 khoảng 11:40 theo kết quả diễn tập và báo cáo của các phiên (142 case; thêm TT-19 đến TT-29, CA-10, CA-11, LO-10, DP-09, DN-13, DN-14, TD-06 đến TD-08). Chưa có chỉnh sửa tay của Khai. Bổ sung sau 11:40 cùng ngày: kết quả các phiên API-1, API-2, WEB-1, WEB-2 và QA tự động, hai ảnh Nhật ký và Giao dịch của Khai. Chỉ TT-25 đánh Đạt (ảnh của Khai); các dòng Lỗi từ QA tự động ghi rõ 'chưa thử tay'.
A4: Cách dùng
A5: Ô cần điền | B5: Chỉ điền ba cột nền vàng nhạt ở sheet Checklist: Trạng thái (chọn từ danh sách), Ngày thử (dd/mm/yyyy) và Ghi chú, bằng chứng. Các cột khác chỉ đọc.
A6: Trạng thái | B6: Chưa làm, Đạt, Lỗi, Chờ thử lại (đã sửa trong code, cần thử lại sau khi rebuild), Bỏ qua (ghi lý do ở Ghi chú). Chỉ đánh Đạt khi chính bạn đã thấy kết quả.
A7: Thêm test case mới | B7: Thêm dòng ngay dưới cuối bảng Checklist (tới dòng 300) và giữ tiền tố mã đúng nhóm, ví dụ TT-19. Sheet Tổng hợp tự tính lại.
A8: Lọc theo vai trò hoặc ưu tiên | B8: Dùng nút lọc ở hàng tiêu đề. Thứ tự đề nghị: nhóm Chuẩn bị, Thanh toán, Ca và tiền mặt, rồi các nhóm còn lại.
A10: Ví dụ điền một dòng
A11: Trạng thái | B11: Đạt
A12: Ngày thử | B12: 03/10/2026
A13: Ghi chú, bằng chứng | B13: PH1003A1012, 80.000đ, tiền về 01:17:59. Webhook 993 ms.
A15: Quy tắc an toàn khi thử
A16: Không chuyển tiền thật | B16: Test mode dùng tài khoản giả. Quét QR bằng app ngân hàng chỉ để xem rồi thoát.
A17: Che thông tin nhạy cảm khi gửi | B17: PIN một lần, khóa whsec_, mã hook trong đường dẫn webhook: che bằng ****** trước khi gửi cho ai.
A18: Khóa và PIN chỉ nhập khi lệnh hỏi ẩn | B18: Không đưa khóa hay PIN vào dòng lệnh.
A19: Dựng lại stack | B19: Sau make rehearse-down rồi make rehearse: mã hook, khóa và PIN đều đổi. Sửa lại URL webhook trong SePay và chạy lại set-secret.
A20: Địa chỉ tunnel đổi mỗi lần | B20: Mỗi lần chạy lại cloudflared, cập nhật URL webhook trong SePay.
A21: Hai vai trò cùng lúc | B21: Phiên đăng nhập dùng cookie: dùng hai profile Chrome, hoặc một cửa sổ thường cộng một cửa sổ ẩn danh, cho mỗi vai trò.
A22: Dữ liệu thử đang dùng
A23: App (máy bạn) | B23: http://localhost:18090/vi/
A24: Mã nhà nghỉ, tài khoản | B24: Mã nhà nghỉ: rehearse. Chủ: owner. Lễ tân: linh. Quản lý và Buồng phòng: tự tạo ở CB-11.
A25: Tài khoản ngân hàng test SePay | B25: 0000000001 (Vietcombank hộ kinh doanh, bắt buộc VA). Tạo VA chính thức SBSEPAY… ở Test mode rồi chọn khi mô phỏng.
A26: Mã phiếu | B26: Hiện trên màn QR của lễ tân, ví dụ PH1003A1012. Dùng nguyên văn làm nội dung khi mô phỏng giao dịch.
A28: Các con số dùng trong test (theo docs/15 và báo cáo của các phiên)
A29: QR hết hạn | B29: 30 phút
A30: Cảnh báo chuyển thiếu | B30: 15 phút sau lần chuyển thiếu đầu tiên, tính theo đồng hồ server. Job chạy mỗi 5 phút.
A31: Khóa đăng nhập | B31: Sai 5 lần thì khóa 15 phút
A32: Sửa giờ vào | B32: Muộn hơn giờ đã ghi tối đa 60 phút, không ở tương lai
A33: Lịch sử lễ tân xem được | B33: 7 ngày gần nhất (chủ đổi được ở Cài đặt)
A34: Cửa sổ chữ ký webhook | B34: 300 giây theo mặc định (SEPAY_TIMESTAMP_TOLERANCE). SePay thử lại tối đa 7 lần trong khoảng 33 phút.
A35: Hạn mức mô phỏng SePay | B35: 500 lượt mỗi ngày

Sheet Tổng hợp
A1: Tổng hợp tiến độ diễn tập
A2: Số liệu tự tính từ sheet Checklist. Không nhập tay ở sheet này.
A4: Nhóm | B4: Tổng | C4: Đạt | D4: Lỗi | E4: Chờ thử lại | F4: Bỏ qua | G4: Chưa làm | H4: Hoàn thành
A5: Chuẩn bị | B5: =COUNTIF(Checklist!$B$2:$B$300,$A5) -> 11 | C5: =COUNTIFS(Checklist!$B$2:$B$300,$A5,Checklist!$H$2:$H$300,"Đạt") -> 5 | D5: =COUNTIFS(Checklist!$B$2:$B$300,$A5,Checklist!$H$2:$H$300,"Lỗi") -> 0 | E5: =COUNTIFS(Checklist!$B$2:$B$300,$A5,Checklist!$H$2:$H$300,"Chờ thử lại") -> 0 | F5: =COUNTIFS(Checklist!$B$2:$B$300,$A5,Checklist!$H$2:$H$300,"Bỏ qua") -> 0 | G5: =B5-C5-D5-E5-F5 -> 6 | H5: =IFERROR(C5/(B5-F5),0) -> 0.45454545
A6: Thanh toán | B6: =COUNTIF(Checklist!$B$2:$B$300,$A6) -> 29 | C6: =COUNTIFS(Checklist!$B$2:$B$300,$A6,Checklist!$H$2:$H$300,"Đạt") -> 8 | D6: =COUNTIFS(Checklist!$B$2:$B$300,$A6,Checklist!$H$2:$H$300,"Lỗi") -> 1 | E6: =COUNTIFS(Checklist!$B$2:$B$300,$A6,Checklist!$H$2:$H$300,"Chờ thử lại") -> 8 | F6: =COUNTIFS(Checklist!$B$2:$B$300,$A6,Checklist!$H$2:$H$300,"Bỏ qua") -> 0 | G6: =B6-C6-D6-E6-F6 -> 12 | H6: =IFERROR(C6/(B6-F6),0) -> 0.27586207
A7: Ca và tiền mặt | B7: =COUNTIF(Checklist!$B$2:$B$300,$A7) -> 11 | C7: =COUNTIFS(Checklist!$B$2:$B$300,$A7,Checklist!$H$2:$H$300,"Đạt") -> 1 | D7: =COUNTIFS(Checklist!$B$2:$B$300,$A7,Checklist!$H$2:$H$300,"Lỗi") -> 0 | E7: =COUNTIFS(Checklist!$B$2:$B$300,$A7,Checklist!$H$2:$H$300,"Chờ thử lại") -> 2 | F7: =COUNTIFS(Checklist!$B$2:$B$300,$A7,Checklist!$H$2:$H$300,"Bỏ qua") -> 0 | G7: =B7-C7-D7-E7-F7 -> 8 | H7: =IFERROR(C7/(B7-F7),0) -> 0.090909091
A8: Lượt ở | B8: =COUNTIF(Checklist!$B$2:$B$300,$A8) -> 10 | C8: =COUNTIFS(Checklist!$B$2:$B$300,$A8,Checklist!$H$2:$H$300,"Đạt") -> 3 | D8: =COUNTIFS(Checklist!$B$2:$B$300,$A8,Checklist!$H$2:$H$300,"Lỗi") -> 0 | E8: =COUNTIFS(Checklist!$B$2:$B$300,$A8,Checklist!$H$2:$H$300,"Chờ thử lại") -> 0 | F8: =COUNTIFS(Checklist!$B$2:$B$300,$A8,Checklist!$H$2:$H$300,"Bỏ qua") -> 0 | G8: =B8-C8-D8-E8-F8 -> 7 | H8: =IFERROR(C8/(B8-F8),0) -> 0.3
A9: Dọn phòng, bảo trì | B9: =COUNTIF(Checklist!$B$2:$B$300,$A9) -> 9 | C9: =COUNTIFS(Checklist!$B$2:$B$300,$A9,Checklist!$H$2:$H$300,"Đạt") -> 0 | D9: =COUNTIFS(Checklist!$B$2:$B$300,$A9,Checklist!$H$2:$H$300,"Lỗi") -> 0 | E9: =COUNTIFS(Checklist!$B$2:$B$300,$A9,Checklist!$H$2:$H$300,"Chờ thử lại") -> 1 | F9: =COUNTIFS(Checklist!$B$2:$B$300,$A9,Checklist!$H$2:$H$300,"Bỏ qua") -> 0 | G9: =B9-C9-D9-E9-F9 -> 8 | H9: =IFERROR(C9/(B9-F9),0) -> 0
A10: Giấy tờ khách | B10: =COUNTIF(Checklist!$B$2:$B$300,$A10) -> 9 | C10: =COUNTIFS(Checklist!$B$2:$B$300,$A10,Checklist!$H$2:$H$300,"Đạt") -> 0 | D10: =COUNTIFS(Checklist!$B$2:$B$300,$A10,Checklist!$H$2:$H$300,"Lỗi") -> 1 | E10: =COUNTIFS(Checklist!$B$2:$B$300,$A10,Checklist!$H$2:$H$300,"Chờ thử lại") -> 0 | F10: =COUNTIFS(Checklist!$B$2:$B$300,$A10,Checklist!$H$2:$H$300,"Bỏ qua") -> 0 | G10: =B10-C10-D10-E10-F10 -> 8 | H10: =IFERROR(C10/(B10-F10),0) -> 0
A11: Đăng nhập, quyền | B11: =COUNTIF(Checklist!$B$2:$B$300,$A11) -> 14 | C11: =COUNTIFS(Checklist!$B$2:$B$300,$A11,Checklist!$H$2:$H$300,"Đạt") -> 0 | D11: =COUNTIFS(Checklist!$B$2:$B$300,$A11,Checklist!$H$2:$H$300,"Lỗi") -> 0 | E11: =COUNTIFS(Checklist!$B$2:$B$300,$A11,Checklist!$H$2:$H$300,"Chờ thử lại") -> 3 | F11: =COUNTIFS(Checklist!$B$2:$B$300,$A11,Checklist!$H$2:$H$300,"Bỏ qua") -> 0 | G11: =B11-C11-D11-E11-F11 -> 11 | H11: =IFERROR(C11/(B11-F11),0) -> 0
A12: Chủ: theo dõi | B12: =COUNTIF(Checklist!$B$2:$B$300,$A12) -> 8 | C12: =COUNTIFS(Checklist!$B$2:$B$300,$A12,Checklist!$H$2:$H$300,"Đạt") -> 0 | D12: =COUNTIFS(Checklist!$B$2:$B$300,$A12,Checklist!$H$2:$H$300,"Lỗi") -> 1 | E12: =COUNTIFS(Checklist!$B$2:$B$300,$A12,Checklist!$H$2:$H$300,"Chờ thử lại") -> 4 | F12: =COUNTIFS(Checklist!$B$2:$B$300,$A12,Checklist!$H$2:$H$300,"Bỏ qua") -> 0 | G12: =B12-C12-D12-E12-F12 -> 3 | H12: =IFERROR(C12/(B12-F12),0) -> 0
A13: Chủ: cài đặt, tài chính, nhân sự | B13: =COUNTIF(Checklist!$B$2:$B$300,$A13) -> 10 | C13: =COUNTIFS(Checklist!$B$2:$B$300,$A13,Checklist!$H$2:$H$300,"Đạt") -> 0 | D13: =COUNTIFS(Checklist!$B$2:$B$300,$A13,Checklist!$H$2:$H$300,"Lỗi") -> 0 | E13: =COUNTIFS(Checklist!$B$2:$B$300,$A13,Checklist!$H$2:$H$300,"Chờ thử lại") -> 0 | F13: =COUNTIFS(Checklist!$B$2:$B$300,$A13,Checklist!$H$2:$H$300,"Bỏ qua") -> 0 | G13: =B13-C13-D13-E13-F13 -> 10 | H13: =IFERROR(C13/(B13-F13),0) -> 0
A14: Bảo mật webhook | B14: =COUNTIF(Checklist!$B$2:$B$300,$A14) -> 5 | C14: =COUNTIFS(Checklist!$B$2:$B$300,$A14,Checklist!$H$2:$H$300,"Đạt") -> 0 | D14: =COUNTIFS(Checklist!$B$2:$B$300,$A14,Checklist!$H$2:$H$300,"Lỗi") -> 0 | E14: =COUNTIFS(Checklist!$B$2:$B$300,$A14,Checklist!$H$2:$H$300,"Chờ thử lại") -> 0 | F14: =COUNTIFS(Checklist!$B$2:$B$300,$A14,Checklist!$H$2:$H$300,"Bỏ qua") -> 0 | G14: =B14-C14-D14-E14-F14 -> 5 | H14: =IFERROR(C14/(B14-F14),0) -> 0
A15: Vận hành, sao lưu | B15: =COUNTIF(Checklist!$B$2:$B$300,$A15) -> 7 | C15: =COUNTIFS(Checklist!$B$2:$B$300,$A15,Checklist!$H$2:$H$300,"Đạt") -> 0 | D15: =COUNTIFS(Checklist!$B$2:$B$300,$A15,Checklist!$H$2:$H$300,"Lỗi") -> 0 | E15: =COUNTIFS(Checklist!$B$2:$B$300,$A15,Checklist!$H$2:$H$300,"Chờ thử lại") -> 0 | F15: =COUNTIFS(Checklist!$B$2:$B$300,$A15,Checklist!$H$2:$H$300,"Bỏ qua") -> 0 | G15: =B15-C15-D15-E15-F15 -> 7 | H15: =IFERROR(C15/(B15-F15),0) -> 0
A16: Giao diện, thiết bị | B16: =COUNTIF(Checklist!$B$2:$B$300,$A16) -> 7 | C16: =COUNTIFS(Checklist!$B$2:$B$300,$A16,Checklist!$H$2:$H$300,"Đạt") -> 0 | D16: =COUNTIFS(Checklist!$B$2:$B$300,$A16,Checklist!$H$2:$H$300,"Lỗi") -> 0 | E16: =COUNTIFS(Checklist!$B$2:$B$300,$A16,Checklist!$H$2:$H$300,"Chờ thử lại") -> 0 | F16: =COUNTIFS(Checklist!$B$2:$B$300,$A16,Checklist!$H$2:$H$300,"Bỏ qua") -> 0 | G16: =B16-C16-D16-E16-F16 -> 7 | H16: =IFERROR(C16/(B16-F16),0) -> 0
A17: Go-live | B17: =COUNTIF(Checklist!$B$2:$B$300,$A17) -> 12 | C17: =COUNTIFS(Checklist!$B$2:$B$300,$A17,Checklist!$H$2:$H$300,"Đạt") -> 0 | D17: =COUNTIFS(Checklist!$B$2:$B$300,$A17,Checklist!$H$2:$H$300,"Lỗi") -> 0 | E17: =COUNTIFS(Checklist!$B$2:$B$300,$A17,Checklist!$H$2:$H$300,"Chờ thử lại") -> 0 | F17: =COUNTIFS(Checklist!$B$2:$B$300,$A17,Checklist!$H$2:$H$300,"Bỏ qua") -> 0 | G17: =B17-C17-D17-E17-F17 -> 12 | H17: =IFERROR(C17/(B17-F17),0) -> 0
A18: Tổng cộng | B18: =SUM(B5:B17) -> 142 | C18: =SUM(C5:C17) -> 17 | D18: =SUM(D5:D17) -> 3 | E18: =SUM(E5:E17) -> 18 | F18: =SUM(F5:F17) -> 0 | G18: =SUM(G5:G17) -> 104 | H18: =IFERROR(C18/(B18-F18),0) -> 0.11971831
A20: Điều kiện go-live
A21: Mục ưu tiên Cao chưa Đạt (không tính Bỏ qua) | B21: =COUNTIFS(Checklist!$G$2:$G$300,"Cao")-COUNTIFS(Checklist!$G$2:$G$300,"Cao",Checklist!$H$2:$H$300,"Đạt")-COUNTIFS(Checklist!$G$2:$G$300,"Cao",Checklist!$H$2:$H$300,"Bỏ qua") -> 78
A22: Số mục đang Lỗi | B22: =D18 -> 3
A23: Kết luận | B23: =IF(AND(B21=0,B22=0),"SẴN SÀNG GO-LIVE","CHƯA SẴN SÀNG") -> CHƯA SẴN SÀNG
A25: Quy tắc go-live: mọi mục ưu tiên Cao phải Đạt (hoặc Bỏ qua kèm lý do ở cột Ghi chú) và không có mục nào Lỗi. Chờ thử lại tính là chưa Đạt. Đây là tiêu chí tự đặt cho dự án, không phải quy định bên ngoài.

Sheet Checklist
A1: Mã | B1: Nhóm | C1: Vai trò | D1: Test case | E1: Các bước | F1: Kết quả mong đợi | G1: Ưu tiên | H1: Trạng thái | I1: Ngày thử | J1: Ghi chú, bằng chứng
A2: CB-01 | B2: Chuẩn bị | C2: Khai | D2: make smoke chạy xanh | E2: 1) cd web && npm ci 2) make smoke | F2: Báo "2 passed" (luồng tiền cơ bản và luồng chuyển thiếu). | G2: Cao | H2: Chưa làm | J2: Số test đã tăng: make smoke hiện chạy 9 spec (WEB-1 báo 9 passed trên máy của lane, chưa phải bạn). Cập nhật kỳ vọng khi bạn thử.
A3: CB-02 | B3: Chuẩn bị | C3: Khai | D3: Dựng stack diễn tập | E3: make rehearse | F3: In ra mã nhà nghỉ, PIN một lần của chủ và lễ tân, đường dẫn webhook. api, db, jobs đang chạy. | G3: Cao | H3: Đạt | I3: 46298 | J3: Chạy được sau khi bỏ MinIO khỏi đường mặc định.
A4: CB-03 | B4: Chuẩn bị | C4: Khai | D4: Số tài khoản nhận tiền khớp tài khoản test SePay | E4: 1) REHEARSE_ACCOUNT_NO=0000000001 make rehearse 2) chạy sepay status | F4: Dòng account hiện ******0001, default=true, CONNECTED. | G4: Cao | H4: Đạt | I4: 46298
A5: CB-04 | B5: Chuẩn bị | C5: Khai | D5: Tunnel Cloudflare chạy | E5: cloudflared tunnel --url http://localhost:18090 | F5: Có địa chỉ https://….trycloudflare.com; SePay gọi được tới app. | G5: Cao | H5: Đạt | I5: 46298 | J5: Địa chỉ đổi mỗi lần chạy lại tunnel: phải sửa URL webhook trong SePay.
A6: CB-05 | B6: Chuẩn bị | C6: Khai | D6: Tạo webhook SePay Test mode | E6: URL = địa chỉ tunnel + đường dẫn webhook; Tiền vào; JSON; tự gửi lại BẬT; "Dùng để xác thực thanh toán" BẬT; "Chỉ gửi khi có mã thanh toán" TẮT; lọc mã để TRỐNG; HMAC-SHA256 | F6: Lưu được. Mô phỏng giao dịch có bản ghi trong Lịch sử gửi. | G6: Cao | H6: Đạt | I6: 46298 | J6: Webhook thành công 993–1147 ms.
A7: CB-06 | B7: Chuẩn bị | C7: Khai | D7: Khóa HMAC khớp giữa SePay và server | E7: 1) set-secret (nhập ẩn) bằng khóa của SePay 2) sepay status | F7: connection CONNECTED, secret stored true, signature check valid. | G7: Cao | H7: Đạt | I7: 46298 | J7: Lần nhận gần nhất 18:10:26 UTC.
A8: CB-07 | B8: Chuẩn bị | C8: Khai | D8: Thay khóa SePay đã dán vào chat | E8: 1) SePay: tạo lại khóa 2) set-secret bằng khóa mới 3) mô phỏng giao dịch | F8: Lịch sử gửi trả 200 với khóa mới. Khóa cũ không còn dùng ở đâu. | G8: Cao | H8: Chưa làm | J8: Khóa cũ đã dán vào chat: tạo lại khóa trong SePay rồi set-secret lại bằng khóa mới.
A9: CB-08 | B9: Chuẩn bị | C9: Khai | D9: Lưu DATA_ENCRYPTION_KEY ngoài bản sao lưu | E9: Chép khóa của từng môi trường vào trình quản lý mật khẩu; production dùng khóa riêng, không dùng khóa của rehearse. | F9: Khóa được lưu tách khỏi bản sao lưu database. Mất khóa thì PIN, CCCD, số tài khoản và khóa SePay không đọc lại được. | G9: Cao | H9: Chưa làm
A10: CB-09 | B10: Chuẩn bị | C10: Lễ tân, Chủ | D10: Đăng nhập lần đầu bắt đặt PIN mới | E10: Đăng nhập owner và linh bằng PIN một lần | F10: Bị yêu cầu đặt PIN mới; PIN 123456 và 111111 bị từ chối. | G10: Vừa | H10: Chưa làm
A11: CB-10 | B11: Chuẩn bị | C11: Khai | D11: Sao lưu và khôi phục thử | E11: make backup-test | F11: PASS: backup-test; số dòng khớp ở mọi bảng (lần trước: 34 bảng). | G11: Cao | H11: Chưa làm
A12: CB-11 | B12: Chuẩn bị | C12: Chủ | D12: Tạo tài khoản Quản lý và Buồng phòng để thử quyền | E12: Chủ: Nhân viên, Thêm. Chọn chức vụ, quyền dùng app, tòa. Lưu PIN một lần. | F12: Hai tài khoản đăng nhập được. Dùng cho các mục Đăng nhập, quyền. | G12: Thấp | H12: Chưa làm
A13: TT-01 | B13: Thanh toán | C13: Lễ tân, SePay | D13: Chuyển khoản đúng tiền, đúng mã phiếu thì tự Đã thanh toán | E13: 1) Lễ tân: nhận phòng, trả phòng, chọn Chuyển khoản 2) SePay, Mô phỏng giao dịch: đúng số tiền, nội dung = mã phiếu trên màn QR (xóa nội dung mặc định), chọn VA 3) Gửi | F13: Màn QR tự chuyển Đã thanh toán trong khoảng 3 giây. Phòng sang Cần dọn. Giao dịch của chủ ghi Khớp phiếu. | G13: Cao | H13: Đạt | I13: 46298 | J13: PH1003A1012, 80.000đ, tiền về 01:17:59.
A14: TT-02 | B14: Thanh toán | C14: Chủ, SePay | D14: Nội dung không có mã phiếu thì Chưa rõ phiếu | E14: Mô phỏng 100.000đ với nội dung mặc định | F14: Giao dịch của chủ: Chưa rõ phiếu, có nút Gán vào phiếu. Không phiếu nào đổi trạng thái. | G14: Cao | H14: Đạt | I14: 46298 | J14: Khoản 100.000đ đang treo, dùng cho TT-03.
A15: TT-03 | B15: Thanh toán | C15: Lễ tân, Chủ | D15: Gán khoản chưa rõ phiếu vào phiếu đúng số tiền | E15: 1) Lễ tân: tạo phiếu còn đúng 100.000đ (A102), chọn Chuyển khoản, KHÔNG mô phỏng tiền 2) Chủ: Giao dịch, Gán vào phiếu 3) Chọn phiếu có nhãn Khớp số tiền, xác nhận | F15: Phiếu Đã thanh toán. Màn QR của lễ tân tự cập nhật. Biên lai có khoản chuyển 100.000đ. Nhật ký ghi việc gán. | G15: Cao | H15: Đạt | I15: 46298 | J15: A102, PH1003A1022, 100.000đ, Khớp phiếu. Chưa xác nhận biên lai và Nhật ký. Giờ hiển thị sai: xem TT-25.
A16: TT-04 | B16: Thanh toán | C16: Chủ | D16: Gán vào phiếu sai số tiền bị từ chối | E16: 1) Mô phỏng 50.000đ, nội dung lạ 2) Tạo phiếu 80.000đ chưa thanh toán 3) Chủ thử gán khoản 50.000đ vào phiếu đó | F16: Phiếu hiện Khác số tiền. Xác nhận bị từ chối, báo số tiền không khớp. Phiếu không đổi. | G16: Cao | H16: Đạt | I16: 46298 | J16: Phiếu Khác số tiền: nút xác nhận bị khóa, hiện "Khoản này 50.000đ, phiếu còn 80.000đ". Lỗi thông báo "đã được gán" (web đọc mã HTTP thay vì mã lỗi) đã sửa. Khoản 50.000đ vẫn treo, dùng cho các test khác.
A17: TT-05 | B17: Thanh toán | C17: Lễ tân | D17: Lễ tân không gán được tiền | E17: Đăng nhập linh, mở trang Giao dịch của chủ | F17: Màn không có quyền. Không có nút Gán. | G17: Cao | H17: Chưa làm | J17: Thử ở đúng tab đang đăng nhập. Mở tab mới thì bị đưa về đăng nhập (sessionStorage mỗi tab): xem DN-07 và DN-13.
A18: TT-06 | B18: Thanh toán | C18: Chủ | D18: Một khoản không gán được hai lần | E18: Sau TT-03, thử gán lại khoản đã gán | F18: Không còn nút gán, hoặc bị từ chối vì đã gán. | G18: Cao | H18: Chưa làm
A19: TT-07 | B19: Thanh toán | C19: Lễ tân, SePay | D19: Chuyển thiếu: QR cho phần còn lại | E19: 1) Phiếu 80.000đ, chọn Chuyển khoản 2) Mô phỏng 70.000đ đúng mã phiếu | F19: Màn hiện Đã nhận 70.000đ, Còn 10.000đ. QR mới đúng 10.000đ, cùng mã phiếu. Không có cảnh báo lệch tiền ngay. Phiếu chưa thanh toán. | G19: Cao | H19: Chưa làm
A20: TT-08 | B20: Thanh toán | C20: SePay | D20: Chuyển bù đủ thì Đã thanh toán | E20: Tiếp TT-07: mô phỏng 10.000đ cùng mã phiếu | F20: Tự thành Đã thanh toán. Biên lai có hai khoản chuyển. | G20: Cao | H20: Chưa làm
A21: TT-09 | B21: Thanh toán | C21: Chủ | D21: Chuyển thiếu để quá 15 phút thì có cảnh báo Chưa thu đủ | E21: Để phiếu đã nhận 70.000đ trên 80.000đ khoảng 15–20 phút | F21: Chủ nhận đúng một cảnh báo Chưa thu đủ, ghi số còn thiếu. Dịch vụ jobs chạy mỗi 5 phút nên có thể trễ tới vài phút. | G21: Cao | H21: Chưa làm
A22: TT-10 | B22: Thanh toán | C22: Lễ tân, SePay | D22: Chuyển thừa | E22: Phiếu 80.000đ, mô phỏng 90.000đ đúng mã | F22: Phiếu Đã thanh toán. Chủ nhận cảnh báo Thừa tiền ghi 10.000đ. | G22: Cao | H22: Chưa làm
A23: TT-11 | B23: Thanh toán | C23: SePay | D23: Giao dịch tiền ra bị bỏ qua | E23: 1) SePay: sửa tạm loại giao dịch của webhook thành Tất cả 2) Mô phỏng Tiền ra 3) Sửa lại về Tiền vào | F23: Không phiếu nào đổi trạng thái. Không hiện như tiền vào. Nhớ đặt lại webhook sau khi thử. | G23: Cao | H23: Lỗi | I23: 46298 | J23: Hiện nút Tiền ra đang bị xám vì webhook chỉ nghe Tiền vào. QA tự động + đọc code, chưa thử tay: tiền ra được lưu thành 'Chưa rõ phiếu' và gán được vào phiếu (InsertPaymentEvent luôn ghi UNMATCHED). Giao API-2 (kết quả IGNORED).
A24: TT-12 | B24: Thanh toán | C24: SePay | D24: Gửi lại cùng giao dịch không tạo trùng | E24: SePay: Lịch sử gửi, gửi lại thủ công một giao dịch đã gửi | F24: Màn Giao dịch không thêm dòng. Tổng tiền không đổi. | G24: Vừa | H24: Chưa làm
A25: TT-13 | B25: Thanh toán | C25: Lễ tân | D25: Cọc lớn hơn hóa đơn thì hoàn tiền mặt | E25: Nhận phòng với cọc 100.000đ, hóa đơn 80.000đ, trả phòng | F25: Không có lựa chọn QR. Chỉ nút Hoàn lại khách 20.000đ (tiền mặt). Phiếu Đã thanh toán. Khoản hoàn nằm trong ca của lễ tân. | G25: Cao | H25: Đạt | I25: 46298 | J25: A101 và A102: chỉ có nút "Hoàn lại khách 20.000đ (tiền mặt)", phòng sang Cần dọn. Dòng hoàn ở Giao dịch hiện "0đ" (TT-25). Sau rebuild dòng hoàn ở Giao dịch hiện −20.000đ, không còn 0đ (xem TT-25).
A26: TT-14 | B26: Thanh toán | C26: Lễ tân | D26: Thanh toán tiền mặt | E26: Trả phòng, chọn Tiền mặt | F26: Đã thanh toán. Giao dịch của chủ ghi Tiền mặt. Tiền mặt dự kiến của ca tăng đúng số. | G26: Cao | H26: Đạt | I26: 46298 | J26: A101, PH1003A101, 80.000đ tiền mặt lúc 00:38.
A27: TT-15 | B27: Thanh toán | C27: Lễ tân | D27: QR hết hạn | E27: Chờ 30 phút (hoặc nhờ dev ép hết hạn trên stack thử), đứng ở màn QR | F27: Màn tự hiện QR hết hạn, có nút tạo QR mới. Tiền chuyển vào mã cũ vẫn được ghi nhận khi SePay báo. | G27: Vừa | H27: Chưa làm
A28: TT-16 | B28: Thanh toán | C28: Lễ tân | D28: Quét QR bằng app ngân hàng thật (không chuyển tiền) | E28: Quét QR rồi THOÁT, không xác nhận chuyển | F28: Đúng tài khoản, số tiền, nội dung = mã phiếu. Ghi vào Ghi chú: ô số tiền và nội dung của từng ngân hàng có sửa được không. | G28: Vừa | H28: Chưa làm | J28: Màn QR lễ tân hiện số tài khoản chính *******0001. Tài khoản Vietcombank hộ kinh doanh bắt buộc VA: xem GL-04.
A29: TT-17 | B29: Thanh toán | C29: SePay | D29: Tiền vào tài khoản khác không tính cho phiếu | E29: 1) SePay: tạo thêm tài khoản test thứ hai 2) Mô phỏng vào tài khoản đó, nội dung = mã phiếu đang chờ | F29: Không phiếu nào thành Đã thanh toán. | G29: Vừa | H29: Chưa làm | J29: Tùy chọn. Nghi cùng nguyên nhân TT-11 (đọc code): tiền vào tài khoản lạ cũng lưu UNMATCHED. Chưa kiểm chứng.
A30: TT-18 | B30: Thanh toán | C30: Lễ tân | D30: Thu tiền mặt cho phần còn thiếu sau khi chuyển thiếu | E30: Phiếu 80.000đ đã nhận 70.000đ, lễ tân chọn thu tiền mặt | F30: Chỉ thu 10.000đ tiền mặt. Phiếu Đã thanh toán. Ca ghi 10.000đ tiền mặt. | G30: Vừa | H30: Chưa làm
A31: TT-19 | B31: Thanh toán | C31: Lễ tân | D31: Trả phòng rồi rời màn thanh toán, quay lại sơ đồ | E31: Trả phòng, chọn chuyển khoản, quay lại sơ đồ phòng (hoặc tải lại trang), chạm phòng đó | F31: Ô phòng ghi Chờ thanh toán kèm số còn thiếu. Khung chi tiết có Tiếp tục thanh toán với đúng mã phiếu cũ. Không có chữ đang bảo trì, không có nút Trả phòng. | G31: Cao | H31: Chờ thử lại | J31: 03/10 08:43: ô phòng đã ghi Chờ thanh toán nhưng khung chi tiết ghi Phòng đang bảo trì (A101, A103). Nguyên nhân: nhánh mặc định của khung chi tiết. API-2 đã đẩy pendingPayment; WEB-1 chưa xong nút tiếp tục. Đã sửa (WEB-1 4c8c1a2): ô Chờ thanh toán, khung có tổng, đã nhận, còn thiếu, Tiếp tục thanh toán, Thu tiền mặt, không có Trả phòng. Chủ và lễ tân, phone và desktop; e2e đạt trên API thật. Thử lại sau rebuild.
A32: TT-20 | B32: Thanh toán | C32: Chủ | D32: Phiếu trả phòng không có tiền sau 30 phút | E32: Trả phòng chuyển khoản, không mô phỏng tiền, chờ khoảng 30 phút | F32: Chủ nhận đúng một cảnh báo Đã trả phòng, chưa thu tiền. Phiếu hiện trong danh sách chưa thu khi kết ca. | G32: Cao | H32: Đạt | I32: 46298 | J32: Cảnh báo "Đã trả phòng, chưa thu tiền" xuất hiện (09:15, 09:23). Nhãn sai cho trường hợp hoàn tiền: xem TT-26.
A33: TT-21 | B33: Thanh toán | C33: Lễ tân | D33: Cọc lớn hơn hóa đơn, rời màn trước khi bấm Hoàn lại | E33: Cọc 100.000đ, hóa đơn 80.000đ, trả phòng, rời màn trước khi hoàn, quay lại phòng | F33: Phòng mở lại được bằng nút Hoàn lại khách. Sau khi bấm: Đã thanh toán, khoản hoàn nằm trong ca. Dữ liệu cũ cũng xử lý được. | G33: Cao | H33: Chờ thử lại | J33: 03/10 08:48: A102 bị kẹt, ô phòng mất loại thuê và giờ ở, không bấm vào được. Đã sửa một phần (WEB-1 f6add89): ô Chờ hoàn ₫X và nút Hoàn lại khách khi mở lại. Mới có unit test, chưa chạy với hoàn cọc thật. Thử lại sau rebuild.
A34: TT-22 | B34: Thanh toán | C34: Lễ tân | D34: Mở màn trả phòng, để vài phút rồi mới thu tiền | E34: Mở màn trả phòng, chờ 3–5 phút, rồi thu tiền | F34: Giờ ra và số tiền đúng theo quy tắc API-2 chọn. Hóa đơn không tự thấp hơn thực tế. | G34: Cao | H34: Chờ thử lại | J34: API-2 phải trả lời: giờ ra chốt lúc mở màn hay lúc xác nhận thanh toán. WEB-1 báo API chốt giờ ra lúc xác nhận thanh toán (rời màn mà chưa xác nhận thì lượt vẫn đang ở). Cần xác nhận lại với API-2 rồi thử tay.
A35: TT-23 | B35: Thanh toán | C35: Lễ tân | D35: Sau khi tải lại trang, mở phòng đã trả phòng mà chưa thanh toán | E35: Trả phòng, chọn chuyển khoản, tải lại trang, chạm phòng đó | F35: Màn tiếp tục thanh toán với đúng mã phiếu cũ. Không hiện lại form trả phòng, không tạo phiếu thanh toán thứ hai. | G35: Cao | H35: Chờ thử lại | J35: 03/10 A103: sau khi tải lại, khung chi tiết quay về màn chọn cách thanh toán. Đã sửa (WEB-1 f6add89): mở lại phòng đã trả sẽ tiếp tục đúng thanh toán cũ, nút QR dùng lại thanh toán đang có. e2e đạt. Thử lại sau rebuild.
A36: TT-24 | B36: Thanh toán | C36: Lễ tân, Chủ | D36: Mở lượt ở đã trả phòng từ nút Xem trong cảnh báo | E36: Chủ: Cảnh báo, Xem một lượt đã trả phòng | F36: Tóm tắt chỉ đọc: Đã trả phòng lúc, trạng thái thanh toán, hóa đơn. Không có Trả phòng, Thêm dịch vụ, Sửa giờ, Chuyển phòng. API từ chối các thao tác đó (409). | G36: Cao | H36: Chờ thử lại | J36: 03/10 10:16: A103 hiện Đã ở 0 giờ và nút Trả phòng. API-2 (409 STAY_NOT_ACTIVE) và WEB-1 (dc15ef9) đã sửa.
A37: TT-25 | B37: Thanh toán | C37: Chủ | D37: Giờ ngân hàng và dòng hoàn tiền ở Giao dịch | E37: Chủ: Giao dịch, xem khoản chuyển đã gán và khoản hoàn cọc | F37: Hiện giờ ngân hàng báo, kèm gán lúc nếu khác. Hoàn cọc hiện số âm (Hoàn tiền mặt −20.000đ), không còn 0đ Tiền mặt. | G37: Vừa | H37: Đạt | I37: 46298 | J37: Khoản 100.000đ về 01:10 hiện 08:33 (giờ gán); hoàn tiền hiện "0đ Tiền mặt". API đã có receivedAt, settledAt, CASH_REFUND; WEB-2 chưa hiển thị. Ảnh chụp lại màn Giao dịch (stack diễn tập, sau rebuild): 100.000đ về 01:10 kèm 'gán lúc 08:33'; hoàn tiền hiện −20.000đ (Hoàn tiền mặt). Chưa xem tab Tiền mặt.
A38: TT-26 | B38: Thanh toán | C38: Lễ tân | D38: Màn trả phòng mở lại hiện đúng tiền cọc | E38: Nhận phòng có cọc, trả phòng, thoát, mở lại màn trả phòng | F38: Dòng Đã cọc bằng đúng cọc, Phải thu = tổng trừ cọc trừ tiền đã nhận. | G38: Cao | H38: Chờ thử lại | J38: 03/10 08:42: A101 ghi cọc 0đ, phải thu 80.000đ. API-2 đối chiếu cọc lúc đọc và sửa dữ liệu cũ; WEB-1 đọc đúng trường. Gốc rễ chưa tái hiện được.
A39: TT-27 | B39: Thanh toán | C39: Chủ | D39: Cảnh báo hoàn tiền không ghi là chưa thu | E39: Chủ: Cảnh báo, xem cảnh báo của phòng có cọc lớn hơn hóa đơn | F39: Hiện "Chờ hoàn 20.000đ cho khách" (REFUND_PENDING), không phải "Còn 20.000đ chưa thu". | G39: Cao | H39: Chờ thử lại | J39: 03/10 A101, A102 ghi "Còn 20.000đ chưa thu". API-2 đã thêm REFUND_PENDING và đổi cảnh báo cũ; WEB-2 đã đọc.
A40: TT-28 | B40: Thanh toán | C40: Khai, Chủ | D40: QR và webhook cho tài khoản bắt buộc VA | E40: 1) Tài khoản bắt buộc VA (Vietcombank hộ kinh doanh) 2) Kiểm tra QR trỏ về VA 3) Mô phỏng giao dịch vào VA | F40: QR trỏ về VA. Webhook khớp theo trường VA. Phiếu thành Đã thanh toán. | G40: Cao | H40: Chưa làm | J40: Hiện QR trỏ số tài khoản chính (*0001). Prompt VA cho API-1 có thể chưa được giao. Cần biết loại tài khoản của nhà nghỉ thật (GL-04).
...
